Workbook
Name Slicer_Month: #N/A
Name Slicer_Year: #N/A

Sheet Dashboard

Sheet Pivots
A3: Row Labels | B3: Sum of Total_Sales
A4: January | B4: 1072821
A5: February | B5: 901743
A6: March | B6: 1001401
A7: April | B7: 991871
A8: May | B8: 1028459
A9: June | B9: 1016595
A10: July | B10: 1017551
A11: August | B11: 1011035
A12: September | B12: 991556
A13: October | B13: 1010560
A14: November | B14: 1006190
A15: December | B15: 986315
A16: Grand Total | B16: 12036097
A22: Row Labels | B22: Average of RevPar
A23: January | B23: 1235.9689
A24: February | B24: 1130.0038
A25: March | B25: 1153.6878
A26: April | B26: 1180.7988
A27: May | B27: 1184.8606
A28: June | B28: 1210.2321
A29: July | B29: 1172.2938
A30: August | B30: 1164.7869
A31: September | B31: 1180.4238
A32: October | B32: 1164.2396
A33: November | B33: 1197.8452
A34: December | B34: 1136.3076
A39: Row Labels | B39: Average of ADR
A40: January | B40: 1574.8226
A41: February | B41: 1460.1754
A42: March | B42: 1476.6613
A43: April | B43: 1520.8833
A44: May | B44: 1488.0968
A45: June | B45: 1524.7667
A46: July | B46: 1529.4032
A47: August | B47: 1507.6774
A48: September | B48: 1507.4333
A49: October | B49: 1523.9839
A50: November | B50: 1476.7
A51: December | B51: 1486.1774
...

Sheet Daily_data
A1: Date | B1: Month_key | C1: Month | D1: Year | E1: Rooms_Occupied | F1: Max_rooms | G1: Occupancy_rate | H1: Room_rate | I1: Total_Sales | J1: OTA Commision | K1: Daily_Rent | L1: Daily_Staff | M1: Daily_HK | N1: Daily_Electricity | O1: Daily Maintenance | P1: Total_Daily_Expense | Q1: Profit | R1: ADR | S1: RevPar
A2: 44927 | B2: =DATE(YEAR(Daily_Data[[#This Row],[Date]]), MONTH(Daily_Data[[#This Row],[Date]]), 1) -> 44927 | C2: =TEXT(Daily_Data[[#This Row],[Month_key]],"mmmm") -> January | D2: =TEXT(Daily_Data[[#This Row],[Month_key]],"yyyy") -> 2023 | E2: 12 | F2: 14 | G2: =Daily_Data[[#This Row],[Rooms_Occupied]]/F2 -> 0.85714286 | H2: 1687 | I2: =Daily_Data[[#This Row],[Room_rate]]*Daily_Data[[#This Row],[Rooms_Occupied]] -> 20244 | J2: =Daily_Data[[#This Row],[Total_Sales]] * 0.22 -> 4453.68 | K2: =INDEX(Expense_master[Monthly_Rent],MATCH(Daily_Data[[#This Row],[Month_key]],Expense_master[Month_Key],0)) / INDEX(Expense_master[Days_in_Month],MATCH(Daily_Data[[#This Row],[Month_key]],Expense_master[Month_Key],0)) -> 6129.0323 | L2: =SUMIFS(Expense_master[Staff_Salary],Expense_master[Month_Key],Daily_Data[[#This Row],[Month_key]]) / SUMIFS(Expense_master[Days_in_Month],Expense_master[Month_Key],Daily_Data[[#This Row],[Month_key]]) -> 2258.0645 | M2: =Daily_Data[[#This Row],[Rooms_Occupied]] * (SUMIFS(Expense_master[Housekeeping_Laundy],Expense_master[Month_Key],Daily_Data[[#This Row],[Month_key]]) / SUMIFS(Occupancy_table[Monthly_rooms_Occupied],Occupancy_table[Month_Key],Daily_Data[[#This Row],[Month_key]])) -> 335.19553 | N2: =0.4 * (SUMIFS(Expense_master[Electicity_Bill],Expense_master[Month_Key],Daily_Data[[#This Row],[Month_key]]) / SUMIFS(Expense_master[Days_in_Month],Expense_master[Month_Key],Daily_Data[[#This Row],[Month_key]])) + Daily_Data[[#This Row],[Rooms_Occupied]] * ( (0.6 * SUMIFS(Expense_master[Electicity_Bill],Expense_master[Month_Key], Daily_Data[[#This Row],[Month_key]])) / SUMIFS(Occupancy_table[Monthly_rooms_Occupied],Occupancy_table[Month_Key],Daily_Data[[#This Row],[Month_key]])) -> 1740.2844 | O2: =SUMIFS(Expense_master[Monthly_Maintenance],Expense_master[Month_Key],Daily_Data[[#This Row],[Month_key]]) / SUMIFS(Expense_master[Days_in_Month],Expense_master[Month_Key], Daily_Data[[#This Row],[Month_key]]) -> 645.16129 | P2: =Daily_Data[[#This Row],[OTA Commision]] + Daily_Data[[#This Row],[Daily_Rent]]+Daily_Data[[#This Row],[Daily_Staff]]+Daily_Data[[#This Row],[Daily_HK]]+Daily_Data[[#This Row],[Daily_Electricity]] + Daily_Data[[#This Row],[Daily Maintenance]] -> 15561.418 | Q2: =Daily_Data[[#This Row],[Total_Sales]]-Daily_Data[[#This Row],[Total_Daily_Expense]] -> 4682.582 | R2: =Daily_Data[[#This Row],[Total_Sales]]/Daily_Data[[#This Row],[Rooms_Occupied]] -> 1687 | S2: =Daily_Data[[#This Row],[Total_Sales]] / Daily_Data[[#This Row],[Max_rooms]] -> 1446
A3: 44928 | B3: =DATE(YEAR(Daily_Data[[#This Row],[Date]]), MONTH(Daily_Data[[#This Row],[Date]]), 1) -> 44927 | C3: =TEXT(Daily_Data[[#This Row],[Month_key]],"mmmm") -> January | D3: =TEXT(Daily_Data[[#This Row],[Month_key]],"yyyy") -> 2023 | E3: 12 | F3: 14 | G3: =Daily_Data[[#This Row],[Rooms_Occupied]]/F3 -> 0.85714286 | H3: 1458 | I3: =Daily_Data[[#This Row],[Room_rate]]*Daily_Data[[#This Row],[Rooms_Occupied]] -> 17496 | J3: =Daily_Data[[#This Row],[Total_Sales]] * 0.22 -> 3849.12 | K3: =INDEX(Expense_master[Monthly_Rent],MATCH(Daily_Data[[#This Row],[Month_key]],Expense_master[Month_Key],0)) / INDEX(Expense_master[Days_in_Month],MATCH(Daily_Data[[#This Row],[Month_key]],Expense_master[Month_Key],0)) -> 6129.0323 | L3: =SUMIFS(Expense_master[Staff_Salary],Expense_master[Month_Key],Daily_Data[[#This Row],[Month_key]]) / SUMIFS(Expense_master[Days_in_Month],Expense_master[Month_Key],Daily_Data[[#This Row],[Month_key]]) -> 2258.0645 | M3: =Daily_Data[[#This Row],[Rooms_Occupied]] * (SUMIFS(Expense_master[Housekeeping_Laundy],Expense_master[Month_Key],Daily_Data[[#This Row],[Month_key]]) / SUMIFS(Occupancy_table[Monthly_rooms_Occupied],Occupancy_table[Month_Key],Daily_Data[[#This Row],[Month_key]])) -> 335.19553 | N3: =0.4 * (SUMIFS(Expense_master[Electicity_Bill],Expense_master[Month_Key],Daily_Data[[#This Row],[Month_key]]) / SUMIFS(Expense_master[Days_in_Month],Expense_master[Month_Key],Daily_Data[[#This Row],[Month_key]])) + Daily_Data[[#This Row],[Rooms_Occupied]] * ( (0.6 * SUMIFS(Expense_master[Electicity_Bill],Expense_master[Month_Key], Daily_Data[[#This Row],[Month_key]])) / SUMIFS(Occupancy_table[Monthly_rooms_Occupied],Occupancy_table[Month_Key],Daily_Data[[#This Row],[Month_key]])) -> 1740.2844 | O3: =SUMIFS(Expense_master[Monthly_Maintenance],Expense_master[Month_Key],Daily_Data[[#This Row],[Month_key]]) / SUMIFS(Expense_master[Days_in_Month],Expense_master[Month_Key], Daily_Data[[#This Row],[Month_key]]) -> 645.16129 | P3: =Daily_Data[[#This Row],[OTA Commision]] + Daily_Data[[#This Row],[Daily_Rent]]+Daily_Data[[#This Row],[Daily_Staff]]+Daily_Data[[#This Row],[Daily_HK]]+Daily_Data[[#This Row],[Daily_Electricity]] + Daily_Data[[#This Row],[Daily Maintenance]] -> 14956.858 | Q3: =Daily_Data[[#This Row],[Total_Sales]]-Daily_Data[[#This Row],[Total_Daily_Expense]] -> 2539.142 | R3: =Daily_Data[[#This Row],[Total_Sales]]/Daily_Data[[#This Row],[Rooms_Occupied]] -> 1458 | S3: =Daily_Data[[#This Row],[Total_Sales]] / Daily_Data[[#This Row],[Max_rooms]] -> 1249.7143
A4: 44929 | B4: =DATE(YEAR(Daily_Data[[#This Row],[Date]]), MONTH(Daily_Data[[#This Row],[Date]]), 1) -> 44927 | C4: =TEXT(Daily_Data[[#This Row],[Month_key]],"mmmm") -> January | D4: =TEXT(Daily_Data[[#This Row],[Month_key]],"yyyy") -> 2023 | E4: 12 | F4: 14 | G4: =Daily_Data[[#This Row],[Rooms_Occupied]]/F4 -> 0.85714286 | H4: 1561 | I4: =Daily_Data[[#This Row],[Room_rate]]*Daily_Data[[#This Row],[Rooms_Occupied]] -> 18732 | J4: =Daily_Data[[#This Row],[Total_Sales]] * 0.22 -> 4121.04 | K4: =INDEX(Expense_master[Monthly_Rent],MATCH(Daily_Data[[#This Row],[Month_key]],Expense_master[Month_Key],0)) / INDEX(Expense_master[Days_in_Month],MATCH(Daily_Data[[#This Row],[Month_key]],Expense_master[Month_Key],0)) -> 6129.0323 | L4: =SUMIFS(Expense_master[Staff_Salary],Expense_master[Month_Key],Daily_Data[[#This Row],[Month_key]]) / SUMIFS(Expense_master[Days_in_Month],Expense_master[Month_Key],Daily_Data[[#This Row],[Month_key]]) -> 2258.0645 | M4: =Daily_Data[[#This Row],[Rooms_Occupied]] * (SUMIFS(Expense_master[Housekeeping_Laundy],Expense_master[Month_Key],Daily_Data[[#This Row],[Month_key]]) / SUMIFS(Occupancy_table[Monthly_rooms_Occupied],Occupancy_table[Month_Key],Daily_Data[[#This Row],[Month_key]])) -> 335.19553 | N4: =0.4 * (SUMIFS(Expense_master[Electicity_Bill],Expense_master[Month_Key],Daily_Data[[#This Row],[Month_key]]) / SUMIFS(Expense_master[Days_in_Month],Expense_master[Month_Key],Daily_Data[[#This Row],[Month_key]])) + Daily_Data[[#This Row],[Rooms_Occupied]] * ( (0.6 * SUMIFS(Expense_master[Electicity_Bill],Expense_master[Month_Key], Daily_Data[[#This Row],[Month_key]])) / SUMIFS(Occupancy_table[Monthly_rooms_Occupied],Occupancy_table[Month_Key],Daily_Data[[#This Row],[Month_key]])) -> 1740.2844 | O4: =SUMIFS(Expense_master[Monthly_Maintenance],Expense_master[Month_Key],Daily_Data[[#This Row],[Month_key]]) / SUMIFS(Expense_master[Days_in_Month],Expense_master[Month_Key], Daily_Data[[#This Row],[Month_key]]) -> 645.16129 | P4: =Daily_Data[[#This Row],[OTA Commision]] + Daily_Data[[#This Row],[Daily_Rent]]+Daily_Data[[#This Row],[Daily_Staff]]+Daily_Data[[#This Row],[Daily_HK]]+Daily_Data[[#This Row],[Daily_Electricity]] + Daily_Data[[#This Row],[Daily Maintenance]] -> 15228.778 | Q4: =Daily_Data[[#This Row],[Total_Sales]]-Daily_Data[[#This Row],[Total_Daily_Expense]] -> 3503.222 | R4: =Daily_Data[[#This Row],[Total_Sales]]/Daily_Data[[#This Row],[Rooms_Occupied]] -> 1561 | S4: =Daily_Data[[#This Row],[Total_Sales]] / Daily_Data[[#This Row],[Max_rooms]] -> 1338
A5: 44930 | B5: =DATE(YEAR(Daily_Data[[#This Row],[Date]]), MONTH(Daily_Data[[#This Row],[Date]]), 1) -> 44927 | C5: =TEXT(Daily_Data[[#This Row],[Month_key]],"mmmm") -> January | D5: =TEXT(Daily_Data[[#This Row],[Month_key]],"yyyy") -> 2023 | E5: 11 | F5: 14 | G5: =Daily_Data[[#This Row],[Rooms_Occupied]]/F5 -> 0.78571429 | H5: 1970 | I5: =Daily_Data[[#This Row],[Room_rate]]*Daily_Data[[#This Row],[Rooms_Occupied]] -> 21670 | J5: =Daily_Data[[#This Row],[Total_Sales]] * 0.22 -> 4767.4 | K5: =INDEX(Expense_master[Monthly_Rent],MATCH(Daily_Data[[#This Row],[Month_key]],Expense_master[Month_Key],0)) / INDEX(Expense_master[Days_in_Month],MATCH(Daily_Data[[#This Row],[Month_key]],Expense_master[Month_Key],0)) -> 6129.0323 | L5: =SUMIFS(Expense_master[Staff_Salary],Expense_master[Month_Key],Daily_Data[[#This Row],[Month_key]]) / SUMIFS(Expense_master[Days_in_Month],Expense_master[Month_Key],Daily_Data[[#This Row],[Month_key]]) -> 2258.0645 | M5: =Daily_Data[[#This Row],[Rooms_Occupied]] * (SUMIFS(Expense_master[Housekeeping_Laundy],Expense_master[Month_Key],Daily_Data[[#This Row],[Month_key]]) / SUMIFS(Occupancy_table[Monthly_rooms_Occupied],Occupancy_table[Month_Key],Daily_Data[[#This Row],[Month_key]])) -> 307.26257 | N5: =0.4 * (SUMIFS(Expense_master[Electicity_Bill],Expense_master[Month_Key],Daily_Data[[#This Row],[Month_key]]) / SUMIFS(Expense_master[Days_in_Month],Expense_master[Month_Key],Daily_Data[[#This Row],[Month_key]])) + Daily_Data[[#This Row],[Rooms_Occupied]] * ( (0.6 * SUMIFS(Expense_master[Electicity_Bill],Expense_master[Month_Key], Daily_Data[[#This Row],[Month_key]])) / SUMIFS(Occupancy_table[Monthly_rooms_Occupied],Occupancy_table[Month_Key],Daily_Data[[#This Row],[Month_key]])) -> 1651.9403 | O5: =SUMIFS(Expense_master[Monthly_Maintenance],Expense_master[Month_Key],Daily_Data[[#This Row],[Month_key]]) / SUMIFS(Expense_master[Days_in_Month],Expense_master[Month_Key], Daily_Data[[#This Row],[Month_key]]) -> 645.16129 | P5: =Daily_Data[[#This Row],[OTA Commision]] + Daily_Data[[#This Row],[Daily_Rent]]+Daily_Data[[#This Row],[Daily_Staff]]+Daily_Data[[#This Row],[Daily_HK]]+Daily_Data[[#This Row],[Daily_Electricity]] + Daily_Data[[#This Row],[Daily Maintenance]] -> 15758.861 | Q5: =Daily_Data[[#This Row],[Total_Sales]]-Daily_Data[[#This Row],[Total_Daily_Expense]] -> 5911.1391 | R5: =Daily_Data[[#This Row],[Total_Sales]]/Daily_Data[[#This Row],[Rooms_Occupied]] -> 1970 | S5: =Daily_Data[[#This Row],[Total_Sales]] / Daily_Data[[#This Row],[Max_rooms]] -> 1547.8571
A6: 44931 | B6: =DATE(YEAR(Daily_Data[[#This Row],[Date]]), MONTH(Daily_Data[[#This Row],[Date]]), 1) -> 44927 | C6: =TEXT(Daily_Data[[#This Row],[Month_key]],"mmmm") -> January | D6: =TEXT(Daily_Data[[#This Row],[Month_key]],"yyyy") -> 2023 | E6: 12 | F6: 14 | G6: =Daily_Data[[#This Row],[Rooms_Occupied]]/F6 -> 0.85714286 | H6: 1556 | I6: =Daily_Data[[#This Row],[Room_rate]]*Daily_Data[[#This Row],[Rooms_Occupied]] -> 18672 | J6: =Daily_Data[[#This Row],[Total_Sales]] * 0.22 -> 4107.84 | K6: =INDEX(Expense_master[Monthly_Rent],MATCH(Daily_Data[[#This Row],[Month_key]],Expense_master[Month_Key],0)) / INDEX(Expense_master[Days_in_Month],MATCH(Daily_Data[[#This Row],[Month_key]],Expense_master[Month_Key],0)) -> 6129.0323 | L6: =SUMIFS(Expense_master[Staff_Salary],Expense_master[Month_Key],Daily_Data[[#This Row],[Month_key]]) / SUMIFS(Expense_master[Days_in_Month],Expense_master[Month_Key],Daily_Data[[#This Row],[Month_key]]) -> 2258.0645 | M6: =Daily_Data[[#This Row],[Rooms_Occupied]] * (SUMIFS(Expense_master[Housekeeping_Laundy],Expense_master[Month_Key],Daily_Data[[#This Row],[Month_key]]) / SUMIFS(Occupancy_table[Monthly_rooms_Occupied],Occupancy_table[Month_Key],Daily_Data[[#This Row],[Month_key]])) -> 335.19553 | N6: =0.4 * (SUMIFS(Expense_master[Electicity_Bill],Expense_master[Month_Key],Daily_Data[[#This Row],[Month_key]]) / SUMIFS(Expense_master[Days_in_Month],Expense_master[Month_Key],Daily_Data[[#This Row],[Month_key]])) + Daily_Data[[#This Row],[Rooms_Occupied]] * ( (0.6 * SUMIFS(Expense_master[Electicity_Bill],Expense_master[Month_Key], Daily_Data[[#This Row],[Month_key]])) / SUMIFS(Occupancy_table[Monthly_rooms_Occupied],Occupancy_table[Month_Key],Daily_Data[[#This Row],[Month_key]])) -> 1740.2844 | O6: =SUMIFS(Expense_master[Monthly_Maintenance],Expense_master[Month_Key],Daily_Data[[#This Row],[Month_key]]) / SUMIFS(Expense_master[Days_in_Month],Expense_master[Month_Key], Daily_Data[[#This Row],[Month_key]]) -> 645.16129 | P6: =Daily_Data[[#This Row],[OTA Commision]] + Daily_Data[[#This Row],[Daily_Rent]]+Daily_Data[[#This Row],[Daily_Staff]]+Daily_Data[[#This Row],[Daily_HK]]+Daily_Data[[#This Row],[Daily_Electricity]] + Daily_Data[[#This Row],[Daily Maintenance]] -> 15215.578 | Q6: =Daily_Data[[#This Row],[Total_Sales]]-Daily_Data[[#This Row],[Total_Daily_Expense]] -> 3456.422 | R6: =Daily_Data[[#This Row],[Total_Sales]]/Daily_Data[[#This Row],[Rooms_Occupied]] -> 1556 | S6: =Daily_Data[[#This Row],[Total_Sales]] / Daily_Data[[#This Row],[Max_rooms]] -> 1333.7143
A7: 44932 | B7: =DATE(YEAR(Daily_Data[[#This Row],[Date]]), MONTH(Daily_Data[[#This Row],[Date]]), 1) -> 44927 | C7: =TEXT(Daily_Data[[#This Row],[Month_key]],"mmmm") -> January | D7: =TEXT(Daily_Data[[#This Row],[Month_key]],"yyyy") -> 2023 | E7: 13 | F7: 14 | G7: =Daily_Data[[#This Row],[Rooms_Occupied]]/F7 -> 0.92857143 | H7: 1572 | I7: =Daily_Data[[#This Row],[Room_rate]]*Daily_Data[[#This Row],[Rooms_Occupied]] -> 20436 | J7: =Daily_Data[[#This Row],[Total_Sales]] * 0.22 -> 4495.92 | K7: =INDEX(Expense_master[Monthly_Rent],MATCH(Daily_Data[[#This Row],[Month_key]],Expense_master[Month_Key],0)) / INDEX(Expense_master[Days_in_Month],MATCH(Daily_Data[[#This Row],[Month_key]],Expense_master[Month_Key],0)) -> 6129.0323 | L7: =SUMIFS(Expense_master[Staff_Salary],Expense_master[Month_Key],Daily_Data[[#This Row],[Month_key]]) / SUMIFS(Expense_master[Days_in_Month],Expense_master[Month_Key],Daily_Data[[#This Row],[Month_key]]) -> 2258.0645 | M7: =Daily_Data[[#This Row],[Rooms_Occupied]] * (SUMIFS(Expense_master[Housekeeping_Laundy],Expense_master[Month_Key],Daily_Data[[#This Row],[Month_key]]) / SUMIFS(Occupancy_table[Monthly_rooms_Occupied],Occupancy_table[Month_Key],Daily_Data[[#This Row],[Month_key]])) -> 363.12849 | N7: =0.4 * (SUMIFS(Expense_master[Electicity_Bill],Expense_master[Month_Key],Daily_Data[[#This Row],[Month_key]]) / SUMIFS(Expense_master[Days_in_Month],Expense_master[Month_Key],Daily_Data[[#This Row],[Month_key]])) + Daily_Data[[#This Row],[Rooms_Occupied]] * ( (0.6 * SUMIFS(Expense_master[Electicity_Bill],Expense_master[Month_Key], Daily_Data[[#This Row],[Month_key]])) / SUMIFS(Occupancy_table[Monthly_rooms_Occupied],Occupancy_table[Month_Key],Daily_Data[[#This Row],[Month_key]])) -> 1828.6286 | O7: =SUMIFS(Expense_master[Monthly_Maintenance],Expense_master[Month_Key],Daily_Data[[#This Row],[Month_key]]) / SUMIFS(Expense_master[Days_in_Month],Expense_master[Month_Key], Daily_Data[[#This Row],[Month_key]]) -> 645.16129 | P7: =Daily_Data[[#This Row],[OTA Commision]] + Daily_Data[[#This Row],[Daily_Rent]]+Daily_Data[[#This Row],[Daily_Staff]]+Daily_Data[[#This Row],[Daily_HK]]+Daily_Data[[#This Row],[Daily_Electricity]] + Daily_Data[[#This Row],[Daily Maintenance]] -> 15719.935 | Q7: =Daily_Data[[#This Row],[Total_Sales]]-Daily_Data[[#This Row],[Total_Daily_Expense]] -> 4716.0649 | R7: =Daily_Data[[#This Row],[Total_Sales]]/Daily_Data[[#This Row],[Rooms_Occupied]] -> 1572 | S7: =Daily_Data[[#This Row],[Total_Sales]] / Daily_Data[[#This Row],[Max_rooms]] -> 1459.7143
A8: 44933 | B8: =DATE(YEAR(Daily_Data[[#This Row],[Date]]), MONTH(Daily_Data[[#This Row],[Date]]), 1) -> 44927 | C8: =TEXT(Daily_Data[[#This Row],[Month_key]],"mmmm") -> January | D8: =TEXT(Daily_Data[[#This Row],[Month_key]],"yyyy") -> 2023 | E8: 14 | F8: 14 | G8: =Daily_Data[[#This Row],[Rooms_Occupied]]/F8 -> 1 | H8: 1922 | I8: =Daily_Data[[#This Row],[Room_rate]]*Daily_Data[[#This Row],[Rooms_Occupied]] -> 26908 | J8: =Daily_Data[[#This Row],[Total_Sales]] * 0.22 -> 5919.76 | K8: =INDEX(Expense_master[Monthly_Rent],MATCH(Daily_Data[[#This Row],[Month_key]],Expense_master[Month_Key],0)) / INDEX(Expense_master[Days_in_Month],MATCH(Daily_Data[[#This Row],[Month_key]],Expense_master[Month_Key],0)) -> 6129.0323 | L8: =SUMIFS(Expense_master[Staff_Salary],Expense_master[Month_Key],Daily_Data[[#This Row],[Month_key]]) / SUMIFS(Expense_master[Days_in_Month],Expense_master[Month_Key],Daily_Data[[#This Row],[Month_key]]) -> 2258.0645 | M8: =Daily_Data[[#This Row],[Rooms_Occupied]] * (SUMIFS(Expense_master[Housekeeping_Laundy],Expense_master[Month_Key],Daily_Data[[#This Row],[Month_key]]) / SUMIFS(Occupancy_table[Monthly_rooms_Occupied],Occupancy_table[Month_Key],Daily_Data[[#This Row],[Month_key]])) -> 391.06145 | N8: =0.4 * (SUMIFS(Expense_master[Electicity_Bill],Expense_master[Month_Key],Daily_Data[[#This Row],[Month_key]]) / SUMIFS(Expense_master[Days_in_Month],Expense_master[Month_Key],Daily_Data[[#This Row],[Month_key]])) + Daily_Data[[#This Row],[Rooms_Occupied]] * ( (0.6 * SUMIFS(Expense_master[Electicity_Bill],Expense_master[Month_Key], Daily_Data[[#This Row],[Month_key]])) / SUMIFS(Occupancy_table[Monthly_rooms_Occupied],Occupancy_table[Month_Key],Daily_Data[[#This Row],[Month_key]])) -> 1916.9727 | O8: =SUMIFS(Expense_master[Monthly_Maintenance],Expense_master[Month_Key],Daily_Data[[#This Row],[Month_key]]) / SUMIFS(Expense_master[Days_in_Month],Expense_master[Month_Key], Daily_Data[[#This Row],[Month_key]]) -> 645.16129 | P8: =Daily_Data[[#This Row],[OTA Commision]] + Daily_Data[[#This Row],[Daily_Rent]]+Daily_Data[[#This Row],[Daily_Staff]]+Daily_Data[[#This Row],[Daily_HK]]+Daily_Data[[#This Row],[Daily_Electricity]] + Daily_Data[[#This Row],[Daily Maintenance]] -> 17260.052 | Q8: =Daily_Data[[#This Row],[Total_Sales]]-Daily_Data[[#This Row],[Total_Daily_Expense]] -> 9647.9478 | R8: =Daily_Data[[#This Row],[Total_Sales]]/Daily_Data[[#This Row],[Rooms_Occupied]] -> 1922 | S8: =Daily_Data[[#This Row],[Total_Sales]] / Daily_Data[[#This Row],[Max_rooms]] -> 1922
A9: 44934 | B9: =DATE(YEAR(Daily_Data[[#This Row],[Date]]), MONTH(Daily_Data[[#This Row],[Date]]), 1) -> 44927 | C9: =TEXT(Daily_Data[[#This Row],[Month_key]],"mmmm") -> January | D9: =TEXT(Daily_Data[[#This Row],[Month_key]],"yyyy") -> 2023 | E9: 13 | F9: 14 | G9: =Daily_Data[[#This Row],[Rooms_Occupied]]/F9 -> 0.92857143 | H9: 1588 | I9: =Daily_Data[[#This Row],[Room_rate]]*Daily_Data[[#This Row],[Rooms_Occupied]] -> 20644 | J9: =Daily_Data[[#This Row],[Total_Sales]] * 0.22 -> 4541.68 | K9: =INDEX(Expense_master[Monthly_Rent],MATCH(Daily_Data[[#This Row],[Month_key]],Expense_master[Month_Key],0)) / INDEX(Expense_master[Days_in_Month],MATCH(Daily_Data[[#This Row],[Month_key]],Expense_master[Month_Key],0)) -> 6129.0323 | L9: =SUMIFS(Expense_master[Staff_Salary],Expense_master[Month_Key],Daily_Data[[#This Row],[Month_key]]) / SUMIFS(Expense_master[Days_in_Month],Expense_master[Month_Key],Daily_Data[[#This Row],[Month_key]]) -> 2258.0645 | M9: =Daily_Data[[#This Row],[Rooms_Occupied]] * (SUMIFS(Expense_master[Housekeeping_Laundy],Expense_master[Month_Key],Daily_Data[[#This Row],[Month_key]]) / SUMIFS(Occupancy_table[Monthly_rooms_Occupied],Occupancy_table[Month_Key],Daily_Data[[#This Row],[Month_key]])) -> 363.12849 | N9: =0.4 * (SUMIFS(Expense_master[Electicity_Bill],Expense_master[Month_Key],Daily_Data[[#This Row],[Month_key]]) / SUMIFS(Expense_master[Days_in_Month],Expense_master[Month_Key],Daily_Data[[#This Row],[Month_key]])) + Daily_Data[[#This Row],[Rooms_Occupied]] * ( (0.6 * SUMIFS(Expense_master[Electicity_Bill],Expense_master[Month_Key], Daily_Data[[#This Row],[Month_key]])) / SUMIFS(Occupancy_table[Monthly_rooms_Occupied],Occupancy_table[Month_Key],Daily_Data[[#This Row],[Month_key]])) -> 1828.6286 | O9: =SUMIFS(Expense_master[Monthly_Maintenance],Expense_master[Month_Key],Daily_Data[[#This Row],[Month_key]]) / SUMIFS(Expense_master[Days_in_Month],Expense_master[Month_Key], Daily_Data[[#This Row],[Month_key]]) -> 645.16129 | P9: =Daily_Data[[#This Row],[OTA Commision]] + Daily_Data[[#This Row],[Daily_Rent]]+Daily_Data[[#This Row],[Daily_Staff]]+Daily_Data[[#This Row],[Daily_HK]]+Daily_Data[[#This Row],[Daily_Electricity]] + Daily_Data[[#This Row],[Daily Maintenance]] -> 15765.695 | Q9: =Daily_Data[[#This Row],[Total_Sales]]-Daily_Data[[#This Row],[Total_Daily_Expense]] -> 4878.3049 | R9: =Daily_Data[[#This Row],[Total_Sales]]/Daily_Data[[#This Row],[Rooms_Occupied]] -> 1588 | S9: =Daily_Data[[#This Row],[Total_Sales]] / Daily_Data[[#This Row],[Max_rooms]] -> 1474.5714 | W9: Total Revenue | X9: =SUM(Daily_Data[Total_Sales]) -> 12036097
A10: 44935 | B10: =DATE(YEAR(Daily_Data[[#This Row],[Date]]), MONTH(Daily_Data[[#This Row],[Date]]), 1) -> 44927 | C10: =TEXT(Daily_Data[[#This Row],[Month_key]],"mmmm") -> January | D10: =TEXT(Daily_Data[[#This Row],[Month_key]],"yyyy") -> 2023 | E10: 12 | F10: 14 | G10: =Daily_Data[[#This Row],[Rooms_Occupied]]/F10 -> 0.85714286 | H10: 1540 | I10: =Daily_Data[[#This Row],[Room_rate]]*Daily_Data[[#This Row],[Rooms_Occupied]] -> 18480 | J10: =Daily_Data[[#This Row],[Total_Sales]] * 0.22 -> 4065.6 | K10: =INDEX(Expense_master[Monthly_Rent],MATCH(Daily_Data[[#This Row],[Month_key]],Expense_master[Month_Key],0)) / INDEX(Expense_master[Days_in_Month],MATCH(Daily_Data[[#This Row],[Month_key]],Expense_master[Month_Key],0)) -> 6129.0323 | L10: =SUMIFS(Expense_master[Staff_Salary],Expense_master[Month_Key],Daily_Data[[#This Row],[Month_key]]) / SUMIFS(Expense_master[Days_in_Month],Expense_master[Month_Key],Daily_Data[[#This Row],[Month_key]]) -> 2258.0645 | M10: =Daily_Data[[#This Row],[Rooms_Occupied]] * (SUMIFS(Expense_master[Housekeeping_Laundy],Expense_master[Month_Key],Daily_Data[[#This Row],[Month_key]]) / SUMIFS(Occupancy_table[Monthly_rooms_Occupied],Occupancy_table[Month_Key],Daily_Data[[#This Row],[Month_key]])) -> 335.19553 | N10: =0.4 * (SUMIFS(Expense_master[Electicity_Bill],Expense_master[Month_Key],Daily_Data[[#This Row],[Month_key]]) / SUMIFS(Expense_master[Days_in_Month],Expense_master[Month_Key],Daily_Data[[#This Row],[Month_key]])) + Daily_Data[[#This Row],[Rooms_Occupied]] * ( (0.6 * SUMIFS(Expense_master[Electicity_Bill],Expense_master[Month_Key], Daily_Data[[#This Row],[Month_key]])) / SUMIFS(Occupancy_table[Monthly_rooms_Occupied],Occupancy_table[Month_Key],Daily_Data[[#This Row],[Month_key]])) -> 1740.2844 | O10: =SUMIFS(Expense_master[Monthly_Maintenance],Expense_master[Month_Key],Daily_Data[[#This Row],[Month_key]]) / SUMIFS(Expense_master[Days_in_Month],Expense_master[Month_Key], Daily_Data[[#This Row],[Month_key]]) -> 645.16129 | P10: =Daily_Data[[#This Row],[OTA Commision]] + Daily_Data[[#This Row],[Daily_Rent]]+Daily_Data[[#This Row],[Daily_Staff]]+Daily_Data[[#This Row],[Daily_HK]]+Daily_Data[[#This Row],[Daily_Electricity]] + Daily_Data[[#This Row],[Daily Maintenance]] -> 15173.338 | Q10: =Daily_Data[[#This Row],[Total_Sales]]-Daily_Data[[#This Row],[Total_Daily_Expense]] -> 3306.662 | R10: =Daily_Data[[#This Row],[Total_Sales]]/Daily_Data[[#This Row],[Rooms_Occupied]] -> 1540 | S10: =Daily_Data[[#This Row],[Total_Sales]] / Daily_Data[[#This Row],[Max_rooms]] -> 1320 | W10: Avg ADR | X10: =AVERAGE(Daily_Data[ADR]) -> 1506.7031
A11: 44936 | B11: =DATE(YEAR(Daily_Data[[#This Row],[Date]]), MONTH(Daily_Data[[#This Row],[Date]]), 1) -> 44927 | C11: =TEXT(Daily_Data[[#This Row],[Month_key]],"mmmm") -> January | D11: =TEXT(Daily_Data[[#This Row],[Month_key]],"yyyy") -> 2023 | E11: 11 | F11: 14 | G11: =Daily_Data[[#This Row],[Rooms_Occupied]]/F11 -> 0.78571429 | H11: 1777 | I11: =Daily_Data[[#This Row],[Room_rate]]*Daily_Data[[#This Row],[Rooms_Occupied]] -> 19547 | J11: =Daily_Data[[#This Row],[Total_Sales]] * 0.22 -> 4300.34 | K11: =INDEX(Expense_master[Monthly_Rent],MATCH(Daily_Data[[#This Row],[Month_key]],Expense_master[Month_Key],0)) / INDEX(Expense_master[Days_in_Month],MATCH(Daily_Data[[#This Row],[Month_key]],Expense_master[Month_Key],0)) -> 6129.0323 | L11: =SUMIFS(Expense_master[Staff_Salary],Expense_master[Month_Key],Daily_Data[[#This Row],[Month_key]]) / SUMIFS(Expense_master[Days_in_Month],Expense_master[Month_Key],Daily_Data[[#This Row],[Month_key]]) -> 2258.0645 | M11: =Daily_Data[[#This Row],[Rooms_Occupied]] * (SUMIFS(Expense_master[Housekeeping_Laundy],Expense_master[Month_Key],Daily_Data[[#This Row],[Month_key]]) / SUMIFS(Occupancy_table[Monthly_rooms_Occupied],Occupancy_table[Month_Key],Daily_Data[[#This Row],[Month_key]])) -> 307.26257 | N11: =0.4 * (SUMIFS(Expense_master[Electicity_Bill],Expense_master[Month_Key],Daily_Data[[#This Row],[Month_key]]) / SUMIFS(Expense_master[Days_in_Month],Expense_master[Month_Key],Daily_Data[[#This Row],[Month_key]])) + Daily_Data[[#This Row],[Rooms_Occupied]] * ( (0.6 * SUMIFS(Expense_master[Electicity_Bill],Expense_master[Month_Key], Daily_Data[[#This Row],[Month_key]])) / SUMIFS(Occupancy_table[Monthly_rooms_Occupied],Occupancy_table[Month_Key],Daily_Data[[#This Row],[Month_key]])) -> 1651.9403 | O11: =SUMIFS(Expense_master[Monthly_Maintenance],Expense_master[Month_Key],Daily_Data[[#This Row],[Month_key]]) / SUMIFS(Expense_master[Days_in_Month],Expense_master[Month_Key], Daily_Data[[#This Row],[Month_key]]) -> 645.16129 | P11: =Daily_Data[[#This Row],[OTA Commision]] + Daily_Data[[#This Row],[Daily_Rent]]+Daily_Data[[#This Row],[Daily_Staff]]+Daily_Data[[#This Row],[Daily_HK]]+Daily_Data[[#This Row],[Daily_Electricity]] + Daily_Data[[#This Row],[Daily Maintenance]] -> 15291.801 | Q11: =Daily_Data[[#This Row],[Total_Sales]]-Daily_Data[[#This Row],[Total_Daily_Expense]] -> 4255.1991 | R11: =Daily_Data[[#This Row],[Total_Sales]]/Daily_Data[[#This Row],[Rooms_Occupied]] -> 1777 | S11: =Daily_Data[[#This Row],[Total_Sales]] / Daily_Data[[#This Row],[Max_rooms]] -> 1396.2143 | W11: Net Profit | X11: =SUM(Daily_Data[Profit]) -> 420821.66
A12: 44937 | B12: =DATE(YEAR(Daily_Data[[#This Row],[Date]]), MONTH(Daily_Data[[#This Row],[Date]]), 1) -> 44927 | C12: =TEXT(Daily_Data[[#This Row],[Month_key]],"mmmm") -> January | D12: =TEXT(Daily_Data[[#This Row],[Month_key]],"yyyy") -> 2023 | E12: 10 | F12: 14 | G12: =Daily_Data[[#This Row],[Rooms_Occupied]]/F12 -> 0.71428571 | H12: 1141 | I12: =Daily_Data[[#This Row],[Room_rate]]*Daily_Data[[#This Row],[Rooms_Occupied]] -> 11410 | J12: =Daily_Data[[#This Row],[Total_Sales]] * 0.22 -> 2510.2 | K12: =INDEX(Expense_master[Monthly_Rent],MATCH(Daily_Data[[#This Row],[Month_key]],Expense_master[Month_Key],0)) / INDEX(Expense_master[Days_in_Month],MATCH(Daily_Data[[#This Row],[Month_key]],Expense_master[Month_Key],0)) -> 6129.0323 | L12: =SUMIFS(Expense_master[Staff_Salary],Expense_master[Month_Key],Daily_Data[[#This Row],[Month_key]]) / SUMIFS(Expense_master[Days_in_Month],Expense_master[Month_Key],Daily_Data[[#This Row],[Month_key]]) -> 2258.0645 | M12: =Daily_Data[[#This Row],[Rooms_Occupied]] * (SUMIFS(Expense_master[Housekeeping_Laundy],Expense_master[Month_Key],Daily_Data[[#This Row],[Month_key]]) / SUMIFS(Occupancy_table[Monthly_rooms_Occupied],Occupancy_table[Month_Key],Daily_Data[[#This Row],[Month_key]])) -> 279.32961 | N12: =0.4 * (SUMIFS(Expense_master[Electicity_Bill],Expense_master[Month_Key],Daily_Data[[#This Row],[Month_key]]) / SUMIFS(Expense_master[Days_in_Month],Expense_master[Month_Key],Daily_Data[[#This Row],[Month_key]])) + Daily_Data[[#This Row],[Rooms_Occupied]] * ( (0.6 * SUMIFS(Expense_master[Electicity_Bill],Expense_master[Month_Key], Daily_Data[[#This Row],[Month_key]])) / SUMIFS(Occupancy_table[Monthly_rooms_Occupied],Occupancy_table[Month_Key],Daily_Data[[#This Row],[Month_key]])) -> 1563.5962 | O12: =SUMIFS(Expense_master[Monthly_Maintenance],Expense_master[Month_Key],Daily_Data[[#This Row],[Month_key]]) / SUMIFS(Expense_master[Days_in_Month],Expense_master[Month_Key], Daily_Data[[#This Row],[Month_key]]) -> 645.16129 | P12: =Daily_Data[[#This Row],[OTA Commision]] + Daily_Data[[#This Row],[Daily_Rent]]+Daily_Data[[#This Row],[Daily_Staff]]+Daily_Data[[#This Row],[Daily_HK]]+Daily_Data[[#This Row],[Daily_Electricity]] + Daily_Data[[#This Row],[Daily Maintenance]] -> 13385.384 | Q12: =Daily_Data[[#This Row],[Total_Sales]]-Daily_Data[[#This Row],[Total_Daily_Expense]] -> -1975.3839 | R12: =Daily_Data[[#This Row],[Total_Sales]]/Daily_Data[[#This Row],[Rooms_Occupied]] -> 1141 | S12: =Daily_Data[[#This Row],[Total_Sales]] / Daily_Data[[#This Row],[Max_rooms]] -> 815 | W12: Total Rooms Sold | X12: =SUM(Daily_Data[Rooms_Occupied]) -> 7974
A13: 44938 | B13: =DATE(YEAR(Daily_Data[[#This Row],[Date]]), MONTH(Daily_Data[[#This Row],[Date]]), 1) -> 44927 | C13: =TEXT(Daily_Data[[#This Row],[Month_key]],"mmmm") -> January | D13: =TEXT(Daily_Data[[#This Row],[Month_key]],"yyyy") -> 2023 | E13: 9 | F13: 14 | G13: =Daily_Data[[#This Row],[Rooms_Occupied]]/F13 -> 0.64285714 | H13: 1316 | I13: =Daily_Data[[#This Row],[Room_rate]]*Daily_Data[[#This Row],[Rooms_Occupied]] -> 11844 | J13: =Daily_Data[[#This Row],[Total_Sales]] * 0.22 -> 2605.68 | K13: =INDEX(Expense_master[Monthly_Rent],MATCH(Daily_Data[[#This Row],[Month_key]],Expense_master[Month_Key],0)) / INDEX(Expense_master[Days_in_Month],MATCH(Daily_Data[[#This Row],[Month_key]],Expense_master[Month_Key],0)) -> 6129.0323 | L13: =SUMIFS(Expense_master[Staff_Salary],Expense_master[Month_Key],Daily_Data[[#This Row],[Month_key]]) / SUMIFS(Expense_master[Days_in_Month],Expense_master[Month_Key],Daily_Data[[#This Row],[Month_key]]) -> 2258.0645 | M13: =Daily_Data[[#This Row],[Rooms_Occupied]] * (SUMIFS(Expense_master[Housekeeping_Laundy],Expense_master[Month_Key],Daily_Data[[#This Row],[Month_key]]) / SUMIFS(Occupancy_table[Monthly_rooms_Occupied],Occupancy_table[Month_Key],Daily_Data[[#This Row],[Month_key]])) -> 251.39665 | N13: =0.4 * (SUMIFS(Expense_master[Electicity_Bill],Expense_master[Month_Key],Daily_Data[[#This Row],[Month_key]]) / SUMIFS(Expense_master[Days_in_Month],Expense_master[Month_Key],Daily_Data[[#This Row],[Month_key]])) + Daily_Data[[#This Row],[Rooms_Occupied]] * ( (0.6 * SUMIFS(Expense_master[Electicity_Bill],Expense_master[Month_Key], Daily_Data[[#This Row],[Month_key]])) / SUMIFS(Occupancy_table[Monthly_rooms_Occupied],Occupancy_table[Month_Key],Daily_Data[[#This Row],[Month_key]])) -> 1475.252 | O13: =SUMIFS(Expense_master[Monthly_Maintenance],Expense_master[Month_Key],Daily_Data[[#This Row],[Month_key]]) / SUMIFS(Expense_master[Days_in_Month],Expense_master[Month_Key], Daily_Data[[#This Row],[Month_key]]) -> 645.16129 | P13: =Daily_Data[[#This Row],[OTA Commision]] + Daily_Data[[#This Row],[Daily_Rent]]+Daily_Data[[#This Row],[Daily_Staff]]+Daily_Data[[#This Row],[Daily_HK]]+Daily_Data[[#This Row],[Daily_Electricity]] + Daily_Data[[#This Row],[Daily Maintenance]] -> 13364.587 | Q13: =Daily_Data[[#This Row],[Total_Sales]]-Daily_Data[[#This Row],[Total_Daily_Expense]] -> -1520.5868 | R13: =Daily_Data[[#This Row],[Total_Sales]]/Daily_Data[[#This Row],[Rooms_Occupied]] -> 1316 | S13: =Daily_Data[[#This Row],[Total_Sales]] / Daily_Data[[#This Row],[Max_rooms]] -> 846 | W13: Average Occupancy | X13: =AVERAGE(Daily_Data[Occupancy_rate]) -> 0.77916748
A14: 44939 | B14: =DATE(YEAR(Daily_Data[[#This Row],[Date]]), MONTH(Daily_Data[[#This Row],[Date]]), 1) -> 44927 | C14: =TEXT(Daily_Data[[#This Row],[Month_key]],"mmmm") -> January | D14: =TEXT(Daily_Data[[#This Row],[Month_key]],"yyyy") -> 2023 | E14: 14 | F14: 14 | G14: =Daily_Data[[#This Row],[Rooms_Occupied]]/F14 -> 1 | H14: 1538 | I14: =Daily_Data[[#This Row],[Room_rate]]*Daily_Data[[#This Row],[Rooms_Occupied]] -> 21532 | J14: =Daily_Data[[#This Row],[Total_Sales]] * 0.22 -> 4737.04 | K14: =INDEX(Expense_master[Monthly_Rent],MATCH(Daily_Data[[#This Row],[Month_key]],Expense_master[Month_Key],0)) / INDEX(Expense_master[Days_in_Month],MATCH(Daily_Data[[#This Row],[Month_key]],Expense_master[Month_Key],0)) -> 6129.0323 | L14: =SUMIFS(Expense_master[Staff_Salary],Expense_master[Month_Key],Daily_Data[[#This Row],[Month_key]]) / SUMIFS(Expense_master[Days_in_Month],Expense_master[Month_Key],Daily_Data[[#This Row],[Month_key]]) -> 2258.0645 | M14: =Daily_Data[[#This Row],[Rooms_Occupied]] * (SUMIFS(Expense_master[Housekeeping_Laundy],Expense_master[Month_Key],Daily_Data[[#This Row],[Month_key]]) / SUMIFS(Occupancy_table[Monthly_rooms_Occupied],Occupancy_table[Month_Key],Daily_Data[[#This Row],[Month_key]])) -> 391.06145 | N14: =0.4 * (SUMIFS(Expense_master[Electicity_Bill],Expense_master[Month_Key],Daily_Data[[#This Row],[Month_key]]) / SUMIFS(Expense_master[Days_in_Month],Expense_master[Month_Key],Daily_Data[[#This Row],[Month_key]])) + Daily_Data[[#This Row],[Rooms_Occupied]] * ( (0.6 * SUMIFS(Expense_master[Electicity_Bill],Expense_master[Month_Key], Daily_Data[[#This Row],[Month_key]])) / SUMIFS(Occupancy_table[Monthly_rooms_Occupied],Occupancy_table[Month_Key],Daily_Data[[#This Row],[Month_key]])) -> 1916.9727 | O14: =SUMIFS(Expense_master[Monthly_Maintenance],Expense_master[Month_Key],Daily_Data[[#This Row],[Month_key]]) / SUMIFS(Expense_master[Days_in_Month],Expense_master[Month_Key], Daily_Data[[#This Row],[Month_key]]) -> 645.16129 | P14: =Daily_Data[[#This Row],[OTA Commision]] + Daily_Data[[#This Row],[Daily_Rent]]+Daily_Data[[#This Row],[Daily_Staff]]+Daily_Data[[#This Row],[Daily_HK]]+Daily_Data[[#This Row],[Daily_Electricity]] + Daily_Data[[#This Row],[Daily Maintenance]] -> 16077.332 | Q14: =Daily_Data[[#This Row],[Total_Sales]]-Daily_Data[[#This Row],[Total_Daily_Expense]] -> 5454.6678 | R14: =Daily_Data[[#This Row],[Total_Sales]]/Daily_Data[[#This Row],[Rooms_Occupied]] -> 1538 | S14: =Daily_Data[[#This Row],[Total_Sales]] / Daily_Data[[#This Row],[Max_rooms]] -> 1538 | W14: Average RevPar | X14: =AVERAGE(Daily_Data[RevPar]) -> 1176.0892
A15: 44940 | B15: =DATE(YEAR(Daily_Data[[#This Row],[Date]]), MONTH(Daily_Data[[#This Row],[Date]]), 1) -> 44927 | C15: =TEXT(Daily_Data[[#This Row],[Month_key]],"mmmm") -> January | D15: =TEXT(Daily_Data[[#This Row],[Month_key]],"yyyy") -> 2023 | E15: 11 | F15: 14 | G15: =Daily_Data[[#This Row],[Rooms_Occupied]]/F15 -> 0.78571429 | H15: 1191 | I15: =Daily_Data[[#This Row],[Room_rate]]*Daily_Data[[#This Row],[Rooms_Occupied]] -> 13101 | J15: =Daily_Data[[#This Row],[Total_Sales]] * 0.22 -> 2882.22 | K15: =INDEX(Expense_master[Monthly_Rent],MATCH(Daily_Data[[#This Row],[Month_key]],Expense_master[Month_Key],0)) / INDEX(Expense_master[Days_in_Month],MATCH(Daily_Data[[#This Row],[Month_key]],Expense_master[Month_Key],0)) -> 6129.0323 | L15: =SUMIFS(Expense_master[Staff_Salary],Expense_master[Month_Key],Daily_Data[[#This Row],[Month_key]]) / SUMIFS(Expense_master[Days_in_Month],Expense_master[Month_Key],Daily_Data[[#This Row],[Month_key]]) -> 2258.0645 | M15: =Daily_Data[[#This Row],[Rooms_Occupied]] * (SUMIFS(Expense_master[Housekeeping_Laundy],Expense_master[Month_Key],Daily_Data[[#This Row],[Month_key]]) / SUMIFS(Occupancy_table[Monthly_rooms_Occupied],Occupancy_table[Month_Key],Daily_Data[[#This Row],[Month_key]])) -> 307.26257 | N15: =0.4 * (SUMIFS(Expense_master[Electicity_Bill],Expense_master[Month_Key],Daily_Data[[#This Row],[Month_key]]) / SUMIFS(Expense_master[Days_in_Month],Expense_master[Month_Key],Daily_Data[[#This Row],[Month_key]])) + Daily_Data[[#This Row],[Rooms_Occupied]] * ( (0.6 * SUMIFS(Expense_master[Electicity_Bill],Expense_master[Month_Key], Daily_Data[[#This Row],[Month_key]])) / SUMIFS(Occupancy_table[Monthly_rooms_Occupied],Occupancy_table[Month_Key],Daily_Data[[#This Row],[Month_key]])) -> 1651.9403 | O15: =SUMIFS(Expense_master[Monthly_Maintenance],Expense_master[Month_Key],Daily_Data[[#This Row],[Month_key]]) / SUMIFS(Expense_master[Days_in_Month],Expense_master[Month_Key], Daily_Data[[#This Row],[Month_key]]) -> 645.16129 | P15: =Daily_Data[[#This Row],[OTA Commision]] + Daily_Data[[#This Row],[Daily_Rent]]+Daily_Data[[#This Row],[Daily_Staff]]+Daily_Data[[#This Row],[Daily_HK]]+Daily_Data[[#This Row],[Daily_Electricity]] + Daily_Data[[#This Row],[Daily Maintenance]] -> 13873.681 | Q15: =Daily_Data[[#This Row],[Total_Sales]]-Daily_Data[[#This Row],[Total_Daily_Expense]] -> -772.68095 | R15: =Daily_Data[[#This Row],[Total_Sales]]/Daily_Data[[#This Row],[Rooms_Occupied]] -> 1191 | S15: =Daily_Data[[#This Row],[Total_Sales]] / Daily_Data[[#This Row],[Max_rooms]] -> 935.78571 | W15: Total Expense | X15: =SUM(Daily_Data[Total_Daily_Expense]) -> 11615275
A16: 44941 | B16: =DATE(YEAR(Daily_Data[[#This Row],[Date]]), MONTH(Daily_Data[[#This Row],[Date]]), 1) -> 44927 | C16: =TEXT(Daily_Data[[#This Row],[Month_key]],"mmmm") -> January | D16: =TEXT(Daily_Data[[#This Row],[Month_key]],"yyyy") -> 2023 | E16: 8 | F16: 14 | G16: =Daily_Data[[#This Row],[Rooms_Occupied]]/F16 -> 0.57142857 | H16: 1864 | I16: =Daily_Data[[#This Row],[Room_rate]]*Daily_Data[[#This Row],[Rooms_Occupied]] -> 14912 | J16: =Daily_Data[[#This Row],[Total_Sales]] * 0.22 -> 3280.64 | K16: =INDEX(Expense_master[Monthly_Rent],MATCH(Daily_Data[[#This Row],[Month_key]],Expense_master[Month_Key],0)) / INDEX(Expense_master[Days_in_Month],MATCH(Daily_Data[[#This Row],[Month_key]],Expense_master[Month_Key],0)) -> 6129.0323 | L16: =SUMIFS(Expense_master[Staff_Salary],Expense_master[Month_Key],Daily_Data[[#This Row],[Month_key]]) / SUMIFS(Expense_master[Days_in_Month],Expense_master[Month_Key],Daily_Data[[#This Row],[Month_key]]) -> 2258.0645 | M16: =Daily_Data[[#This Row],[Rooms_Occupied]] * (SUMIFS(Expense_master[Housekeeping_Laundy],Expense_master[Month_Key],Daily_Data[[#This Row],[Month_key]]) / SUMIFS(Occupancy_table[Monthly_rooms_Occupied],Occupancy_table[Month_Key],Daily_Data[[#This Row],[Month_key]])) -> 223.46369 | N16: =0.4 * (SUMIFS(Expense_master[Electicity_Bill],Expense_master[Month_Key],Daily_Data[[#This Row],[Month_key]]) / SUMIFS(Expense_master[Days_in_Month],Expense_master[Month_Key],Daily_Data[[#This Row],[Month_key]])) + Daily_Data[[#This Row],[Rooms_Occupied]] * ( (0.6 * SUMIFS(Expense_master[Electicity_Bill],Expense_master[Month_Key], Daily_Data[[#This Row],[Month_key]])) / SUMIFS(Occupancy_table[Monthly_rooms_Occupied],Occupancy_table[Month_Key],Daily_Data[[#This Row],[Month_key]])) -> 1386.9079 | O16: =SUMIFS(Expense_master[Monthly_Maintenance],Expense_master[Month_Key],Daily_Data[[#This Row],[Month_key]]) / SUMIFS(Expense_master[Days_in_Month],Expense_master[Month_Key], Daily_Data[[#This Row],[Month_key]]) -> 645.16129 | P16: =Daily_Data[[#This Row],[OTA Commision]] + Daily_Data[[#This Row],[Daily_Rent]]+Daily_Data[[#This Row],[Daily_Staff]]+Daily_Data[[#This Row],[Daily_HK]]+Daily_Data[[#This Row],[Daily_Electricity]] + Daily_Data[[#This Row],[Daily Maintenance]] -> 13923.27 | Q16: =Daily_Data[[#This Row],[Total_Sales]]-Daily_Data[[#This Row],[Total_Daily_Expense]] -> 988.73034 | R16: =Daily_Data[[#This Row],[Total_Sales]]/Daily_Data[[#This Row],[Rooms_Occupied]] -> 1864 | S16: =Daily_Data[[#This Row],[Total_Sales]] / Daily_Data[[#This Row],[Max_rooms]] -> 1065.1429 | W16: OTA Commission | X16: =Daily_Data[OTA Commision] / Daily_Data[Total_Sales] -> 0.22
A17: 44942 | B17: =DATE(YEAR(Daily_Data[[#This Row],[Date]]), MONTH(Daily_Data[[#This Row],[Date]]), 1) -> 44927 | C17: =TEXT(Daily_Data[[#This Row],[Month_key]],"mmmm") -> January | D17: =TEXT(Daily_Data[[#This Row],[Month_key]],"yyyy") -> 2023 | E17: 13 | F17: 14 | G17: =Daily_Data[[#This Row],[Rooms_Occupied]]/F17 -> 0.92857143 | H17: 1479 | I17: =Daily_Data[[#This Row],[Room_rate]]*Daily_Data[[#This Row],[Rooms_Occupied]] -> 19227 | J17: =Daily_Data[[#This Row],[Total_Sales]] * 0.22 -> 4229.94 | K17: =INDEX(Expense_master[Monthly_Rent],MATCH(Daily_Data[[#This Row],[Month_key]],Expense_master[Month_Key],0)) / INDEX(Expense_master[Days_in_Month],MATCH(Daily_Data[[#This Row],[Month_key]],Expense_master[Month_Key],0)) -> 6129.0323 | L17: =SUMIFS(Expense_master[Staff_Salary],Expense_master[Month_Key],Daily_Data[[#This Row],[Month_key]]) / SUMIFS(Expense_master[Days_in_Month],Expense_master[Month_Key],Daily_Data[[#This Row],[Month_key]]) -> 2258.0645 | M17: =Daily_Data[[#This Row],[Rooms_Occupied]] * (SUMIFS(Expense_master[Housekeeping_Laundy],Expense_master[Month_Key],Daily_Data[[#This Row],[Month_key]]) / SUMIFS(Occupancy_table[Monthly_rooms_Occupied],Occupancy_table[Month_Key],Daily_Data[[#This Row],[Month_key]])) -> 363.12849 | N17: =0.4 * (SUMIFS(Expense_master[Electicity_Bill],Expense_master[Month_Key],Daily_Data[[#This Row],[Month_key]]) / SUMIFS(Expense_master[Days_in_Month],Expense_master[Month_Key],Daily_Data[[#This Row],[Month_key]])) + Daily_Data[[#This Row],[Rooms_Occupied]] * ( (0.6 * SUMIFS(Expense_master[Electicity_Bill],Expense_master[Month_Key], Daily_Data[[#This Row],[Month_key]])) / SUMIFS(Occupancy_table[Monthly_rooms_Occupied],Occupancy_table[Month_Key],Daily_Data[[#This Row],[Month_key]])) -> 1828.6286 | O17: =SUMIFS(Expense_master[Monthly_Maintenance],Expense_master[Month_Key],Daily_Data[[#This Row],[Month_key]]) / SUMIFS(Expense_master[Days_in_Month],Expense_master[Month_Key], Daily_Data[[#This Row],[Month_key]]) -> 645.16129 | P17: =Daily_Data[[#This Row],[OTA Commision]] + Daily_Data[[#This Row],[Daily_Rent]]+Daily_Data[[#This Row],[Daily_Staff]]+Daily_Data[[#This Row],[Daily_HK]]+Daily_Data[[#This Row],[Daily_Electricity]] + Daily_Data[[#This Row],[Daily Maintenance]] -> 15453.955 | Q17: =Daily_Data[[#This Row],[Total_Sales]]-Daily_Data[[#This Row],[Total_Daily_Expense]] -> 3773.0449 | R17: =Daily_Data[[#This Row],[Total_Sales]]/Daily_Data[[#This Row],[Rooms_Occupied]] -> 1479 | S17: =Daily_Data[[#This Row],[Total_Sales]] / Daily_Data[[#This Row],[Max_rooms]] -> 1373.3571 | W17: Highest Revenue Month
A18: 44943 | B18: =DATE(YEAR(Daily_Data[[#This Row],[Date]]), MONTH(Daily_Data[[#This Row],[Date]]), 1) -> 44927 | C18: =TEXT(Daily_Data[[#This Row],[Month_key]],"mmmm") -> January | D18: =TEXT(Daily_Data[[#This Row],[Month_key]],"yyyy") -> 2023 | E18: 10 | F18: 14 | G18: =Daily_Data[[#This Row],[Rooms_Occupied]]/F18 -> 0.71428571 | H18: 1513 | I18: =Daily_Data[[#This Row],[Room_rate]]*Daily_Data[[#This Row],[Rooms_Occupied]] -> 15130 | J18: =Daily_Data[[#This Row],[Total_Sales]] * 0.22 -> 3328.6 | K18: =INDEX(Expense_master[Monthly_Rent],MATCH(Daily_Data[[#This Row],[Month_key]],Expense_master[Month_Key],0)) / INDEX(Expense_master[Days_in_Month],MATCH(Daily_Data[[#This Row],[Month_key]],Expense_master[Month_Key],0)) -> 6129.0323 | L18: =SUMIFS(Expense_master[Staff_Salary],Expense_master[Month_Key],Daily_Data[[#This Row],[Month_key]]) / SUMIFS(Expense_master[Days_in_Month],Expense_master[Month_Key],Daily_Data[[#This Row],[Month_key]]) -> 2258.0645 | M18: =Daily_Data[[#This Row],[Rooms_Occupied]] * (SUMIFS(Expense_master[Housekeeping_Laundy],Expense_master[Month_Key],Daily_Data[[#This Row],[Month_key]]) / SUMIFS(Occupancy_table[Monthly_rooms_Occupied],Occupancy_table[Month_Key],Daily_Data[[#This Row],[Month_key]])) -> 279.32961 | N18: =0.4 * (SUMIFS(Expense_master[Electicity_Bill],Expense_master[Month_Key],Daily_Data[[#This Row],[Month_key]]) / SUMIFS(Expense_master[Days_in_Month],Expense_master[Month_Key],Daily_Data[[#This Row],[Month_key]])) + Daily_Data[[#This Row],[Rooms_Occupied]] * ( (0.6 * SUMIFS(Expense_master[Electicity_Bill],Expense_master[Month_Key], Daily_Data[[#This Row],[Month_key]])) / SUMIFS(Occupancy_table[Monthly_rooms_Occupied],Occupancy_table[Month_Key],Daily_Data[[#This Row],[Month_key]])) -> 1563.5962 | O18: =SUMIFS(Expense_master[Monthly_Maintenance],Expense_master[Month_Key],Daily_Data[[#This Row],[Month_key]]) / SUMIFS(Expense_master[Days_in_Month],Expense_master[Month_Key], Daily_Data[[#This Row],[Month_key]]) -> 645.16129 | P18: =Daily_Data[[#This Row],[OTA Commision]] + Daily_Data[[#This Row],[Daily_Rent]]+Daily_Data[[#This Row],[Daily_Staff]]+Daily_Data[[#This Row],[Daily_HK]]+Daily_Data[[#This Row],[Daily_Electricity]] + Daily_Data[[#This Row],[Daily Maintenance]] -> 14203.784 | Q18: =Daily_Data[[#This Row],[Total_Sales]]-Daily_Data[[#This Row],[Total_Daily_Expense]] -> 926.21615 | R18: =Daily_Data[[#This Row],[Total_Sales]]/Daily_Data[[#This Row],[Rooms_Occupied]] -> 1513 | S18: =Daily_Data[[#This Row],[Total_Sales]] / Daily_Data[[#This Row],[Max_rooms]] -> 1080.7143 | W18: Lowest Revenue Month
A19: 44944 | B19: =DATE(YEAR(Daily_Data[[#This Row],[Date]]), MONTH(Daily_Data[[#This Row],[Date]]), 1) -> 44927 | C19: =TEXT(Daily_Data[[#This Row],[Month_key]],"mmmm") -> January | D19: =TEXT(Daily_Data[[#This Row],[Month_key]],"yyyy") -> 2023 | E19: 10 | F19: 14 | G19: =Daily_Data[[#This Row],[Rooms_Occupied]]/F19 -> 0.71428571 | H19: 1577 | I19: =Daily_Data[[#This Row],[Room_rate]]*Daily_Data[[#This Row],[Rooms_Occupied]] -> 15770 | J19: =Daily_Data[[#This Row],[Total_Sales]] * 0.22 -> 3469.4 | K19: =INDEX(Expense_master[Monthly_Rent],MATCH(Daily_Data[[#This Row],[Month_key]],Expense_master[Month_Key],0)) / INDEX(Expense_master[Days_in_Month],MATCH(Daily_Data[[#This Row],[Month_key]],Expense_master[Month_Key],0)) -> 6129.0323 | L19: =SUMIFS(Expense_master[Staff_Salary],Expense_master[Month_Key],Daily_Data[[#This Row],[Month_key]]) / SUMIFS(Expense_master[Days_in_Month],Expense_master[Month_Key],Daily_Data[[#This Row],[Month_key]]) -> 2258.0645 | M19: =Daily_Data[[#This Row],[Rooms_Occupied]] * (SUMIFS(Expense_master[Housekeeping_Laundy],Expense_master[Month_Key],Daily_Data[[#This Row],[Month_key]]) / SUMIFS(Occupancy_table[Monthly_rooms_Occupied],Occupancy_table[Month_Key],Daily_Data[[#This Row],[Month_key]])) -> 279.32961 | N19: =0.4 * (SUMIFS(Expense_master[Electicity_Bill],Expense_master[Month_Key],Daily_Data[[#This Row],[Month_key]]) / SUMIFS(Expense_master[Days_in_Month],Expense_master[Month_Key],Daily_Data[[#This Row],[Month_key]])) + Daily_Data[[#This Row],[Rooms_Occupied]] * ( (0.6 * SUMIFS(Expense_master[Electicity_Bill],Expense_master[Month_Key], Daily_Data[[#This Row],[Month_key]])) / SUMIFS(Occupancy_table[Monthly_rooms_Occupied],Occupancy_table[Month_Key],Daily_Data[[#This Row],[Month_key]])) -> 1563.5962 | O19: =SUMIFS(Expense_master[Monthly_Maintenance],Expense_master[Month_Key],Daily_Data[[#This Row],[Month_key]]) / SUMIFS(Expense_master[Days_in_Month],Expense_master[Month_Key], Daily_Data[[#This Row],[Month_key]]) -> 645.16129 | P19: =Daily_Data[[#This Row],[OTA Commision]] + Daily_Data[[#This Row],[Daily_Rent]]+Daily_Data[[#This Row],[Daily_Staff]]+Daily_Data[[#This Row],[Daily_HK]]+Daily_Data[[#This Row],[Daily_Electricity]] + Daily_Data[[#This Row],[Daily Maintenance]] -> 14344.584 | Q19: =Daily_Data[[#This Row],[Total_Sales]]-Daily_Data[[#This Row],[Total_Daily_Expense]] -> 1425.4161 | R19: =Daily_Data[[#This Row],[Total_Sales]]/Daily_Data[[#This Row],[Rooms_Occupied]] -> 1577 | S19: =Daily_Data[[#This Row],[Total_Sales]] / Daily_Data[[#This Row],[Max_rooms]] -> 1126.4286 | W19: highest RevPar grwoth %
A20: 44945 | B20: =DATE(YEAR(Daily_Data[[#This Row],[Date]]), MONTH(Daily_Data[[#This Row],[Date]]), 1) -> 44927 | C20: =TEXT(Daily_Data[[#This Row],[Month_key]],"mmmm") -> January | D20: =TEXT(Daily_Data[[#This Row],[Month_key]],"yyyy") -> 2023 | E20: 10 | F20: 14 | G20: =Daily_Data[[#This Row],[Rooms_Occupied]]/F20 -> 0.71428571 | H20: 1282 | I20: =Daily_Data[[#This Row],[Room_rate]]*Daily_Data[[#This Row],[Rooms_Occupied]] -> 12820 | J20: =Daily_Data[[#This Row],[Total_Sales]] * 0.22 -> 2820.4 | K20: =INDEX(Expense_master[Monthly_Rent],MATCH(Daily_Data[[#This Row],[Month_key]],Expense_master[Month_Key],0)) / INDEX(Expense_master[Days_in_Month],MATCH(Daily_Data[[#This Row],[Month_key]],Expense_master[Month_Key],0)) -> 6129.0323 | L20: =SUMIFS(Expense_master[Staff_Salary],Expense_master[Month_Key],Daily_Data[[#This Row],[Month_key]]) / SUMIFS(Expense_master[Days_in_Month],Expense_master[Month_Key],Daily_Data[[#This Row],[Month_key]]) -> 2258.0645 | M20: =Daily_Data[[#This Row],[Rooms_Occupied]] * (SUMIFS(Expense_master[Housekeeping_Laundy],Expense_master[Month_Key],Daily_Data[[#This Row],[Month_key]]) / SUMIFS(Occupancy_table[Monthly_rooms_Occupied],Occupancy_table[Month_Key],Daily_Data[[#This Row],[Month_key]])) -> 279.32961 | N20: =0.4 * (SUMIFS(Expense_master[Electicity_Bill],Expense_master[Month_Key],Daily_Data[[#This Row],[Month_key]]) / SUMIFS(Expense_master[Days_in_Month],Expense_master[Month_Key],Daily_Data[[#This Row],[Month_key]])) + Daily_Data[[#This Row],[Rooms_Occupied]] * ( (0.6 * SUMIFS(Expense_master[Electicity_Bill],Expense_master[Month_Key], Daily_Data[[#This Row],[Month_key]])) / SUMIFS(Occupancy_table[Monthly_rooms_Occupied],Occupancy_table[Month_Key],Daily_Data[[#This Row],[Month_key]])) -> 1563.5962 | O20: =SUMIFS(Expense_master[Monthly_Maintenance],Expense_master[Month_Key],Daily_Data[[#This Row],[Month_key]]) / SUMIFS(Expense_master[Days_in_Month],Expense_master[Month_Key], Daily_Data[[#This Row],[Month_key]]) -> 645.16129 | P20: =Daily_Data[[#This Row],[OTA Commision]] + Daily_Data[[#This Row],[Daily_Rent]]+Daily_Data[[#This Row],[Daily_Staff]]+Daily_Data[[#This Row],[Daily_HK]]+Daily_Data[[#This Row],[Daily_Electricity]] + Daily_Data[[#This Row],[Daily Maintenance]] -> 13695.584 | Q20: =Daily_Data[[#This Row],[Total_Sales]]-Daily_Data[[#This Row],[Total_Daily_Expense]] -> -875.58385 | R20: =Daily_Data[[#This Row],[Total_Sales]]/Daily_Data[[#This Row],[Rooms_Occupied]] -> 1282 | S20: =Daily_Data[[#This Row],[Total_Sales]] / Daily_Data[[#This Row],[Max_rooms]] -> 915.71429 | W20: CPOR | X20: =Daily_Data[Total_Daily_Expense] / Daily_Data[Rooms_Occupied] -> 1369.5584
A21: 44946 | B21: =DATE(YEAR(Daily_Data[[#This Row],[Date]]), MONTH(Daily_Data[[#This Row],[Date]]), 1) -> 44927 | C21: =TEXT(Daily_Data[[#This Row],[Month_key]],"mmmm") -> January | D21: =TEXT(Daily_Data[[#This Row],[Month_key]],"yyyy") -> 2023 | E21: 9 | F21: 14 | G21: =Daily_Data[[#This Row],[Rooms_Occupied]]/F21 -> 0.64285714 | H21: 1339 | I21: =Daily_Data[[#This Row],[Room_rate]]*Daily_Data[[#This Row],[Rooms_Occupied]] -> 12051 | J21: =Daily_Data[[#This Row],[Total_Sales]] * 0.22 -> 2651.22 | K21: =INDEX(Expense_master[Monthly_Rent],MATCH(Daily_Data[[#This Row],[Month_key]],Expense_master[Month_Key],0)) / INDEX(Expense_master[Days_in_Month],MATCH(Daily_Data[[#This Row],[Month_key]],Expense_master[Month_Key],0)) -> 6129.0323 | L21: =SUMIFS(Expense_master[Staff_Salary],Expense_master[Month_Key],Daily_Data[[#This Row],[Month_key]]) / SUMIFS(Expense_master[Days_in_Month],Expense_master[Month_Key],Daily_Data[[#This Row],[Month_key]]) -> 2258.0645 | M21: =Daily_Data[[#This Row],[Rooms_Occupied]] * (SUMIFS(Expense_master[Housekeeping_Laundy],Expense_master[Month_Key],Daily_Data[[#This Row],[Month_key]]) / SUMIFS(Occupancy_table[Monthly_rooms_Occupied],Occupancy_table[Month_Key],Daily_Data[[#This Row],[Month_key]])) -> 251.39665 | N21: =0.4 * (SUMIFS(Expense_master[Electicity_Bill],Expense_master[Month_Key],Daily_Data[[#This Row],[Month_key]]) / SUMIFS(Expense_master[Days_in_Month],Expense_master[Month_Key],Daily_Data[[#This Row],[Month_key]])) + Daily_Data[[#This Row],[Rooms_Occupied]] * ( (0.6 * SUMIFS(Expense_master[Electicity_Bill],Expense_master[Month_Key], Daily_Data[[#This Row],[Month_key]])) / SUMIFS(Occupancy_table[Monthly_rooms_Occupied],Occupancy_table[Month_Key],Daily_Data[[#This Row],[Month_key]])) -> 1475.252 | O21: =SUMIFS(Expense_master[Monthly_Maintenance],Expense_master[Month_Key],Daily_Data[[#This Row],[Month_key]]) / SUMIFS(Expense_master[Days_in_Month],Expense_master[Month_Key], Daily_Data[[#This Row],[Month_key]]) -> 645.16129 | P21: =Daily_Data[[#This Row],[OTA Commision]] + Daily_Data[[#This Row],[Daily_Rent]]+Daily_Data[[#This Row],[Daily_Staff]]+Daily_Data[[#This Row],[Daily_HK]]+Daily_Data[[#This Row],[Daily_Electricity]] + Daily_Data[[#This Row],[Daily Maintenance]] -> 13410.127 | Q21: =Daily_Data[[#This Row],[Total_Sales]]-Daily_Data[[#This Row],[Total_Daily_Expense]] -> -1359.1268 | R21: =Daily_Data[[#This Row],[Total_Sales]]/Daily_Data[[#This Row],[Rooms_Occupied]] -> 1339 | S21: =Daily_Data[[#This Row],[Total_Sales]] / Daily_Data[[#This Row],[Max_rooms]] -> 860.78571
A22: 44947 | B22: =DATE(YEAR(Daily_Data[[#This Row],[Date]]), MONTH(Daily_Data[[#This Row],[Date]]), 1) -> 44927 | C22: =TEXT(Daily_Data[[#This Row],[Month_key]],"mmmm") -> January | D22: =TEXT(Daily_Data[[#This Row],[Month_key]],"yyyy") -> 2023 | E22: 14 | F22: 14 | G22: =Daily_Data[[#This Row],[Rooms_Occupied]]/F22 -> 1 | H22: 1405 | I22: =Daily_Data[[#This Row],[Room_rate]]*Daily_Data[[#This Row],[Rooms_Occupied]] -> 19670 | J22: =Daily_Data[[#This Row],[Total_Sales]] * 0.22 -> 4327.4 | K22: =INDEX(Expense_master[Monthly_Rent],MATCH(Daily_Data[[#This Row],[Month_key]],Expense_master[Month_Key],0)) / INDEX(Expense_master[Days_in_Month],MATCH(Daily_Data[[#This Row],[Month_key]],Expense_master[Month_Key],0)) -> 6129.0323 | L22: =SUMIFS(Expense_master[Staff_Salary],Expense_master[Month_Key],Daily_Data[[#This Row],[Month_key]]) / SUMIFS(Expense_master[Days_in_Month],Expense_master[Month_Key],Daily_Data[[#This Row],[Month_key]]) -> 2258.0645 | M22: =Daily_Data[[#This Row],[Rooms_Occupied]] * (SUMIFS(Expense_master[Housekeeping_Laundy],Expense_master[Month_Key],Daily_Data[[#This Row],[Month_key]]) / SUMIFS(Occupancy_table[Monthly_rooms_Occupied],Occupancy_table[Month_Key],Daily_Data[[#This Row],[Month_key]])) -> 391.06145 | N22: =0.4 * (SUMIFS(Expense_master[Electicity_Bill],Expense_master[Month_Key],Daily_Data[[#This Row],[Month_key]]) / SUMIFS(Expense_master[Days_in_Month],Expense_master[Month_Key],Daily_Data[[#This Row],[Month_key]])) + Daily_Data[[#This Row],[Rooms_Occupied]] * ( (0.6 * SUMIFS(Expense_master[Electicity_Bill],Expense_master[Month_Key], Daily_Data[[#This Row],[Month_key]])) / SUMIFS(Occupancy_table[Monthly_rooms_Occupied],Occupancy_table[Month_Key],Daily_Data[[#This Row],[Month_key]])) -> 1916.9727 | O22: =SUMIFS(Expense_master[Monthly_Maintenance],Expense_master[Month_Key],Daily_Data[[#This Row],[Month_key]]) / SUMIFS(Expense_master[Days_in_Month],Expense_master[Month_Key], Daily_Data[[#This Row],[Month_key]]) -> 645.16129 | P22: =Daily_Data[[#This Row],[OTA Commision]] + Daily_Data[[#This Row],[Daily_Rent]]+Daily_Data[[#This Row],[Daily_Staff]]+Daily_Data[[#This Row],[Daily_HK]]+Daily_Data[[#This Row],[Daily_Electricity]] + Daily_Data[[#This Row],[Daily Maintenance]] -> 15667.692 | Q22: =Daily_Data[[#This Row],[Total_Sales]]-Daily_Data[[#This Row],[Total_Daily_Expense]] -> 4002.3078 | R22: =Daily_Data[[#This Row],[Total_Sales]]/Daily_Data[[#This Row],[Rooms_Occupied]] -> 1405 | S22: =Daily_Data[[#This Row],[Total_Sales]] / Daily_Data[[#This Row],[Max_rooms]] -> 1405
A23: 44948 | B23: =DATE(YEAR(Daily_Data[[#This Row],[Date]]), MONTH(Daily_Data[[#This Row],[Date]]), 1) -> 44927 | C23: =TEXT(Daily_Data[[#This Row],[Month_key]],"mmmm") -> January | D23: =TEXT(Daily_Data[[#This Row],[Month_key]],"yyyy") -> 2023 | E23: 14 | F23: 14 | G23: =Daily_Data[[#This Row],[Rooms_Occupied]]/F23 -> 1 | H23: 1513 | I23: =Daily_Data[[#This Row],[Room_rate]]*Daily_Data[[#This Row],[Rooms_Occupied]] -> 21182 | J23: =Daily_Data[[#This Row],[Total_Sales]] * 0.22 -> 4660.04 | K23: =INDEX(Expense_master[Monthly_Rent],MATCH(Daily_Data[[#This Row],[Month_key]],Expense_master[Month_Key],0)) / INDEX(Expense_master[Days_in_Month],MATCH(Daily_Data[[#This Row],[Month_key]],Expense_master[Month_Key],0)) -> 6129.0323 | L23: =SUMIFS(Expense_master[Staff_Salary],Expense_master[Month_Key],Daily_Data[[#This Row],[Month_key]]) / SUMIFS(Expense_master[Days_in_Month],Expense_master[Month_Key],Daily_Data[[#This Row],[Month_key]]) -> 2258.0645 | M23: =Daily_Data[[#This Row],[Rooms_Occupied]] * (SUMIFS(Expense_master[Housekeeping_Laundy],Expense_master[Month_Key],Daily_Data[[#This Row],[Month_key]]) / SUMIFS(Occupancy_table[Monthly_rooms_Occupied],Occupancy_table[Month_Key],Daily_Data[[#This Row],[Month_key]])) -> 391.06145 | N23: =0.4 * (SUMIFS(Expense_master[Electicity_Bill],Expense_master[Month_Key],Daily_Data[[#This Row],[Month_key]]) / SUMIFS(Expense_master[Days_in_Month],Expense_master[Month_Key],Daily_Data[[#This Row],[Month_key]])) + Daily_Data[[#This Row],[Rooms_Occupied]] * ( (0.6 * SUMIFS(Expense_master[Electicity_Bill],Expense_master[Month_Key], Daily_Data[[#This Row],[Month_key]])) / SUMIFS(Occupancy_table[Monthly_rooms_Occupied],Occupancy_table[Month_Key],Daily_Data[[#This Row],[Month_key]])) -> 1916.9727 | O23: =SUMIFS(Expense_master[Monthly_Maintenance],Expense_master[Month_Key],Daily_Data[[#This Row],[Month_key]]) / SUMIFS(Expense_master[Days_in_Month],Expense_master[Month_Key], Daily_Data[[#This Row],[Month_key]]) -> 645.16129 | P23: =Daily_Data[[#This Row],[OTA Commision]] + Daily_Data[[#This Row],[Daily_Rent]]+Daily_Data[[#This Row],[Daily_Staff]]+Daily_Data[[#This Row],[Daily_HK]]+Daily_Data[[#This Row],[Daily_Electricity]] + Daily_Data[[#This Row],[Daily Maintenance]] -> 16000.332 | Q23: =Daily_Data[[#This Row],[Total_Sales]]-Daily_Data[[#This Row],[Total_Daily_Expense]] -> 5181.6678 | R23: =Daily_Data[[#This Row],[Total_Sales]]/Daily_Data[[#This Row],[Rooms_Occupied]] -> 1513 | S23: =Daily_Data[[#This Row],[Total_Sales]] / Daily_Data[[#This Row],[Max_rooms]] -> 1513
